<?xml version="1.0"?>
<sdf version="1.9">
  <model name="panda_scaled_03">
    <link name="panda_link0">
      <visual name="panda_link0_visual">
        <geometry>
          <mesh>
            <uri>meshes/visual/link0.dae</uri><scale>0.3 0.3 0.3</scale>
          </mesh>
        </geometry>
      </visual>
      <collision name="panda_link0_collision">
        <geometry>
          <mesh>
            <uri>meshes/collision/link0.stl</uri><scale>0.3 0.3 0.3</scale>
          </mesh>
        </geometry>
      </collision>
      <inertial>
        <pose>-0.00767 -8.6e-06 0.0172 0 0 0</pose>
        <mass>0.1</mass>
        <inertia><ixx>1e-08</ixx><iyy>1e-08</iyy><izz>1e-08</izz><ixy>0</ixy><ixz>0</ixz><iyz>0</iyz></inertia>
      </inertial>
    </link>

    <link name="panda_link1">
      <pose relative_to="panda_joint1">0 0 0 0 0 0</pose>
      <visual name="panda_link1_visual">
        <geometry>
          <mesh>
            <uri>meshes/visual/link1.dae</uri><scale>0.3 0.3 0.3</scale>
          </mesh>
        </geometry>
      </visual>
      <collision name="panda_link1_collision">
        <geometry>
          <mesh>
            <uri>meshes/collision/link1.stl</uri><scale>0.3 0.3 0.3</scale>
          </mesh>
        </geometry>
      </collision>
      <inertial>
        <pose>-1.1e-09 -0.00975 -0.02027 0 0 0</pose>
        <mass>0.1</mass>
        <inertia><ixx>1e-08</ixx><iyy>1e-08</iyy><izz>1e-08</izz><ixy>0</ixy><ixz>0</ixz><iyz>0</iyz></inertia>
      </inertial>
    </link>

    <link name="panda_link2">
      <pose relative_to="panda_joint2">0 0 0 0 0 0</pose>
      <visual name="panda_link2_visual">
        <geometry>
          <mesh>
            <uri>meshes/visual/link2.dae</uri><scale>0.3 0.3 0.3</scale>
          </mesh>
        </geometry>
      </visual>
      <collision name="panda_link2_collision">
        <geometry>
          <mesh>
            <uri>meshes/collision/link2.stl</uri><scale>0.3 0.3 0.3</scale>
          </mesh>
        </geometry>
      </collision>
      <inertial>
        <pose>9.5e-08 -0.02058 0.00967 0 0 0</pose>
        <mass>0.1</mass>
        <inertia><ixx>1e-08</ixx><iyy>1e-08</iyy><izz>1e-08</izz><ixy>0</ixy><ixz>0</ixz><iyz>0</iyz></inertia>
      </inertial>
    </link>

    <link name="panda_link3">
      <pose relative_to="panda_joint3">0 0 0 0 0 0</pose>
      <visual name="panda_link3_visual">
        <geometry>
          <mesh>
            <uri>meshes/visual/link3.dae</uri><scale>0.3 0.3 0.3</scale>
          </mesh>
        </geometry>
      </visual>
      <collision name="panda_link3_collision">
        <geometry>
          <mesh>
            <uri>meshes/collision/link3.stl</uri><scale>0.3 0.3 0.3</scale>
          </mesh>
        </geometry>
      </collision>
      <inertial>
        <pose>0.0141 0.00949 -0.00951 0 0 0</pose>
        <mass>0.1</mass>
        <inertia><ixx>1e-08</ixx><iyy>1e-08</iyy><izz>1e-08</izz><ixy>0</ixy><ixz>0</ixz><iyz>0</iyz></inertia>
      </inertial>
    </link>

    <link name="panda_link4">
      <pose relative_to="panda_joint4">0 0 0 0 0 0</pose>
      <visual name="panda_link4_visual">
        <geometry>
          <mesh>
            <uri>meshes/visual/link4.dae</uri><scale>0.3 0.3 0.3</scale>
          </mesh>
        </geometry>
      </visual>
      <collision name="panda_link4_collision">
        <geometry>
          <mesh>
            <uri>meshes/collision/link4.stl</uri><scale>0.3 0.3 0.3</scale>
          </mesh>
        </geometry>
      </collision>
      <inertial>
        <pose>-0.0108 0.0101 0.00957 0 0 0</pose>
        <mass>0.1</mass>
        <inertia><ixx>1e-08</ixx><iyy>1e-08</iyy><izz>1e-08</izz><ixy>0</ixy><ixz>0</ixz><iyz>0</iyz></inertia>
      </inertial>
    </link>

    <link name="panda_link5">
      <pose relative_to="panda_joint5">0 0 0 0 0 0</pose>
      <visual name="panda_link5_visual">
        <geometry>
          <mesh>
            <uri>meshes/visual/link5.dae</uri><scale>0.3 0.3 0.3</scale>
          </mesh>
        </geometry>
      </visual>
      <collision name="panda_link5_collision">
        <geometry>
          <mesh>
            <uri>meshes/collision/link5.stl</uri><scale>0.3 0.3 0.3</scale>
          </mesh>
        </geometry>
      </collision>
      <inertial>
        <pose>-1.8e-06 0.01831 -0.03125 0 0 0</pose>
        <mass>0.1</mass>
        <inertia><ixx>1e-08</ixx><iyy>1e-08</iyy><izz>1e-08</izz><ixy>0</ixy><ixz>0</ixz><iyz>0</iyz></inertia>
      </inertial>
    </link>

    <link name="panda_link6">
      <pose relative_to="panda_joint6">0 0 0 0 0 0</pose>
      <visual name="panda_link6_visual">
        <geometry>
          <mesh>
            <uri>meshes/visual/link6.dae</uri><scale>0.3 0.3 0.3</scale>
          </mesh>
        </geometry>
      </visual>
      <collision name="panda_link6_collision">
        <geometry>
          <mesh>
            <uri>meshes/collision/link6.stl</uri><scale>0.3 0.3 0.3</scale>
          </mesh>
        </geometry>
      </collision>
      <inertial>
        <pose>0.0153 0.00273 0.00319 0 0 0</pose>
        <mass>0.1</mass>
        <inertia><ixx>1e-08</ixx><iyy>1e-08</iyy><izz>1e-08</izz><ixy>0</ixy><ixz>0</ixz><iyz>0</iyz></inertia>
      </inertial>
    </link>

    <link name="panda_link7">
      <pose relative_to="panda_joint7">0 0 0 0 0 0</pose>
      <visual name="panda_link7_visual">
        <geometry>
          <mesh>
            <uri>meshes/visual/link7.dae</uri><scale>0.3 0.3 0.3</scale>
          </mesh>
        </geometry>
      </visual>
      <collision name="panda_link7_collision">
        <geometry>
          <mesh>
            <uri>meshes/collision/link7.stl</uri><scale>0.3 0.3 0.3</scale>
          </mesh>
        </geometry>
      </collision>
      <inertial>
        <pose>0.00329 0.00324 0.01951 0 0 0</pose>
        <mass>0.1</mass>
        <inertia><ixx>1e-08</ixx><iyy>1e-08</iyy><izz>1e-08</izz><ixy>0</ixy><ixz>0</ixz><iyz>0</iyz></inertia>
      </inertial>
    </link>

    <joint name="panda_joint1" type="revolute">
      <pose relative_to="panda_link0">0 0 0.0999 0 0 0</pose>
      <parent>panda_link0</parent>
      <child>panda_link1</child>
      <axis>
        <xyz>0 0 1</xyz>
        <limit><effort>87</effort><lower>-2.897</lower><upper>2.897</upper><velocity>2.617</velocity></limit>
        <dynamics><damping>1.0</damping><friction>0.1</friction></dynamics>
      </axis>
    </joint>

    <joint name="panda_joint2" type="revolute">
      <pose relative_to="panda_link1">0 0 0 -1.570796 0 0</pose>
      <parent>panda_link1</parent>
      <child>panda_link2</child>
      <axis>
        <xyz>0 0 1</xyz>
        <limit><effort>87</effort><lower>-1.762</lower><upper>1.762</upper><velocity>2.617</velocity></limit>
        <dynamics><damping>1.0</damping><friction>0.1</friction></dynamics>
      </axis>
    </joint>

    <joint name="panda_joint3" type="revolute">
      <pose relative_to="panda_link2">0 -0.0948 0 1.570796 0 0</pose>
      <parent>panda_link2</parent>
      <child>panda_link3</child>
      <axis>
        <xyz>0 0 1</xyz>
        <limit><effort>87</effort><lower>-2.897</lower><upper>2.897</upper><velocity>2.617</velocity></limit>
        <dynamics><damping>1.0</damping><friction>0.1</friction></dynamics>
      </axis>
    </joint>

    <joint name="panda_joint4" type="revolute">
      <pose relative_to="panda_link3">0.02475 0 0 1.570796 0 0</pose>
      <parent>panda_link3</parent>
      <child>panda_link4</child>
      <axis>
        <xyz>0 0 1</xyz>
        <limit><effort>87</effort><lower>-3.071</lower><upper>-0.069</upper><velocity>2.617</velocity></limit>
        <dynamics><damping>1.0</damping><friction>0.1</friction></dynamics>
      </axis>
    </joint>

    <joint name="panda_joint5" type="revolute">
      <pose relative_to="panda_link4">-0.02475 0.1152 0 -1.570796 0 0</pose>
      <parent>panda_link4</parent>
      <child>panda_link5</child>
      <axis>
        <xyz>0 0 1</xyz>
        <limit><effort>12</effort><lower>-2.897</lower><upper>2.897</upper><velocity>3.141</velocity></limit>
        <dynamics><damping>0.1</damping><friction>0.01</friction></dynamics>
      </axis>
    </joint>

    <joint name="panda_joint6" type="revolute">
      <pose relative_to="panda_link5">0 0 0 1.570796 0 0</pose>
      <parent>panda_link5</parent>
      <child>panda_link6</child>
      <axis>
        <xyz>0 0 1</xyz>
        <limit><effort>12</effort><lower>-0.017</lower><upper>3.752</upper><velocity>3.141</velocity></limit>
        <dynamics><damping>0.1</damping><friction>0.01</friction></dynamics>
      </axis>
    </joint>

    <joint name="panda_joint7" type="revolute">
      <pose relative_to="panda_link6">0.0264 0 0 1.570796 -0.8 0</pose>
      <parent>panda_link6</parent>
      <child>panda_link7</child>
      <axis>
        <xyz>0 0 1</xyz>
        <limit><effort>12</effort><lower>-2.897</lower><upper>2.897</upper><velocity>3.141</velocity></limit>
        <dynamics><damping>0.1</damping><friction>0.01</friction></dynamics>
      </axis>
    </joint>

    <frame name="gripper_mount" attached_to="panda_link7">
      <pose>0 0 0.0321 0 0 -0.785398</pose>
    </frame>

    <plugin filename="gz-sim-joint-position-controller-system" name="gz::sim::systems::JointPositionController">
    <joint_name>panda_joint1</joint_name>
    <sub_topic>panda_joint1/cmd_pos</sub_topic>
    <p_gain>10</p_gain>
    <d_gain>1</d_gain>
    </plugin>
    <plugin filename="gz-sim-joint-position-controller-system" name="gz::sim::systems::JointPositionController">
    <joint_name>panda_joint2</joint_name>
    <sub_topic>panda_joint2/cmd_pos</sub_topic>
    <p_gain>500</p_gain><d_gain>10</d_gain>
    </plugin>
    <plugin filename="gz-sim-joint-position-controller-system" name="gz::sim::systems::JointPositionController">
    <joint_name>panda_joint3</joint_name>
    <sub_topic>panda_joint3/cmd_pos</sub_topic>
    <p_gain>10</p_gain><d_gain>1</d_gain>
    </plugin>
    <plugin filename="gz-sim-joint-position-controller-system" name="gz::sim::systems::JointPositionController">
    <joint_name>panda_joint4</joint_name>
    <sub_topic>panda_joint4/cmd_pos</sub_topic>
    <p_gain>50</p_gain><d_gain>2</d_gain>
    </plugin>
    <plugin filename="gz-sim-joint-position-controller-system" name="gz::sim::systems::JointPositionController">
    <joint_name>panda_joint5</joint_name>
    <sub_topic>panda_joint5/cmd_pos</sub_topic>
    <p_gain>5</p_gain><d_gain>0.5</d_gain>
    </plugin>
    <plugin filename="gz-sim-joint-position-controller-system" name="gz::sim::systems::JointPositionController">
    <joint_name>panda_joint6</joint_name>
    <sub_topic>panda_joint6/cmd_pos</sub_topic>
    <p_gain>5</p_gain><d_gain>0.5</d_gain>
    </plugin>
    <plugin filename="gz-sim-joint-position-controller-system" name="gz::sim::systems::JointPositionController">
    <joint_name>panda_joint7</joint_name>
    <sub_topic>panda_joint7/cmd_pos</sub_topic>
    <p_gain>1</p_gain><d_gain>0.01</d_gain>
    </plugin>

  </model>
</sdf>